<?xml version="1.0" encoding="UTF-8"?>
<!-- Generated by org.testng.reporters.JUnitReportReporter -->
<testsuite hostname="IND157" name="testSuit.KnowledgeBaseLoginTest" tests="2" failures="2" timestamp="25 May 2018 06:10:40 GMT" time="0.013" errors="0">
  <testcase name="testLoginWithValidCredentialsInMobiControl" time="0.012" classname="testSuit.KnowledgeBaseLoginTest">
    <failure type="java.lang.AssertionError" message="Login failed due to following exception ">
      <![CDATA[java.lang.AssertionError: Login failed due to following exception 
	at org.testng.Assert.fail(Assert.java:83)
	at testSuit.KnowledgeBaseLoginTest.testLoginWithValidCredentialsInMobiControl(KnowledgeBaseLoginTest.java:56)
	at sun.reflect.NativeMethodAccessorImpl.invoke0(Native Method)
	at sun.reflect.NativeMethodAccessorImpl.invoke(Unknown Source)
	at sun.reflect.DelegatingMethodAccessorImpl.invoke(Unknown Source)
	at java.lang.reflect.Method.invoke(Unknown Source)
	at org.testng.internal.MethodInvocationHelper.invokeMethod(MethodInvocationHelper.java:85)
	at org.testng.internal.Invoker.invokeMethod(Invoker.java:639)
	at org.testng.internal.Invoker.invokeTestMethod(Invoker.java:816)
	at org.testng.internal.Invoker.invokeTestMethods(Invoker.java:1124)
	at org.testng.internal.TestMethodWorker.invokeTestMethods(TestMethodWorker.java:125)
	at org.testng.internal.TestMethodWorker.run(TestMethodWorker.java:108)
	at org.testng.TestRunner.privateRun(TestRunner.java:774)
	at org.testng.TestRunner.run(TestRunner.java:624)
	at org.testng.SuiteRunner.runTest(SuiteRunner.java:359)
	at org.testng.SuiteRunner.runSequentially(SuiteRunner.java:354)
	at org.testng.SuiteRunner.privateRun(SuiteRunner.java:312)
	at org.testng.SuiteRunner.run(SuiteRunner.java:261)
	at org.testng.SuiteRunnerWorker.runSuite(SuiteRunnerWorker.java:52)
	at org.testng.SuiteRunnerWorker.run(SuiteRunnerWorker.java:86)
	at org.testng.TestNG.runSuitesSequentially(TestNG.java:1215)
	at org.testng.TestNG.runSuitesLocally(TestNG.java:1140)
	at org.testng.TestNG.run(TestNG.java:1048)
	at org.testng.remote.AbstractRemoteTestNG.run(AbstractRemoteTestNG.java:114)
	at org.testng.remote.RemoteTestNG.initAndRun(RemoteTestNG.java:251)
	at org.testng.remote.RemoteTestNG.main(RemoteTestNG.java:77)
Caused by: java.lang.NullPointerException
	at com.google.common.base.Preconditions.checkNotNull(Preconditions.java:882)
	at org.openqa.selenium.support.ui.FluentWait.<init>(FluentWait.java:104)
	at org.openqa.selenium.support.ui.WebDriverWait.<init>(WebDriverWait.java:71)
	at org.openqa.selenium.support.ui.WebDriverWait.<init>(WebDriverWait.java:45)
	at utilities.utilityFunctions.waitForElementToBeClickable(utilityFunctions.java:19)
	at knowledgeBasePages.HomePage.loginMobiControl(HomePage.java:49)
	at testSuit.KnowledgeBaseLoginTest.testLoginWithValidCredentialsInMobiControl(KnowledgeBaseLoginTest.java:49)
	... 24 more
]]>
    </failure>
  </testcase> <!-- testLoginWithValidCredentialsInMobiControl -->
  <testcase name="testLoginWithInvalidCrerdentialsInMobicontrol" time="0.001" classname="testSuit.KnowledgeBaseLoginTest">
    <failure type="java.lang.AssertionError" message="Login with invalid credentials failed due to following exception ">
      <![CDATA[java.lang.AssertionError: Login with invalid credentials failed due to following exception 
	at org.testng.Assert.fail(Assert.java:83)
	at testSuit.KnowledgeBaseLoginTest.testLoginWithInvalidCrerdentialsInMobicontrol(KnowledgeBaseLoginTest.java:73)
	at sun.reflect.NativeMethodAccessorImpl.invoke0(Native Method)
	at sun.reflect.NativeMethodAccessorImpl.invoke(Unknown Source)
	at sun.reflect.DelegatingMethodAccessorImpl.invoke(Unknown Source)
	at java.lang.reflect.Method.invoke(Unknown Source)
	at org.testng.internal.MethodInvocationHelper.invokeMethod(MethodInvocationHelper.java:85)
	at org.testng.internal.Invoker.invokeMethod(Invoker.java:639)
	at org.testng.internal.Invoker.invokeTestMethod(Invoker.java:816)
	at org.testng.internal.Invoker.invokeTestMethods(Invoker.java:1124)
	at org.testng.internal.TestMethodWorker.invokeTestMethods(TestMethodWorker.java:125)
	at org.testng.internal.TestMethodWorker.run(TestMethodWorker.java:108)
	at org.testng.TestRunner.privateRun(TestRunner.java:774)
	at org.testng.TestRunner.run(TestRunner.java:624)
	at org.testng.SuiteRunner.runTest(SuiteRunner.java:359)
	at org.testng.SuiteRunner.runSequentially(SuiteRunner.java:354)
	at org.testng.SuiteRunner.privateRun(SuiteRunner.java:312)
	at org.testng.SuiteRunner.run(SuiteRunner.java:261)
	at org.testng.SuiteRunnerWorker.runSuite(SuiteRunnerWorker.java:52)
	at org.testng.SuiteRunnerWorker.run(SuiteRunnerWorker.java:86)
	at org.testng.TestNG.runSuitesSequentially(TestNG.java:1215)
	at org.testng.TestNG.runSuitesLocally(TestNG.java:1140)
	at org.testng.TestNG.run(TestNG.java:1048)
	at org.testng.remote.AbstractRemoteTestNG.run(AbstractRemoteTestNG.java:114)
	at org.testng.remote.RemoteTestNG.initAndRun(RemoteTestNG.java:251)
	at org.testng.remote.RemoteTestNG.main(RemoteTestNG.java:77)
Caused by: java.lang.NullPointerException
	at com.google.common.base.Preconditions.checkNotNull(Preconditions.java:882)
	at org.openqa.selenium.support.ui.FluentWait.<init>(FluentWait.java:104)
	at org.openqa.selenium.support.ui.WebDriverWait.<init>(WebDriverWait.java:71)
	at org.openqa.selenium.support.ui.WebDriverWait.<init>(WebDriverWait.java:45)
	at utilities.utilityFunctions.waitForElementToBeClickable(utilityFunctions.java:19)
	at knowledgeBasePages.HomePage.loginMobiControl(HomePage.java:49)
	at testSuit.KnowledgeBaseLoginTest.testLoginWithInvalidCrerdentialsInMobicontrol(KnowledgeBaseLoginTest.java:65)
	... 24 more
]]>
    </failure>
  </testcase> <!-- testLoginWithInvalidCrerdentialsInMobicontrol -->
</testsuite> <!-- testSuit.KnowledgeBaseLoginTest -->
